Workbook

Sheet Datos históricos de Credicorp (
C2: Analisis Cuantitativo de las Acciones de Credicorp
C3: (En Dólares)
D5: Inicio | F5: =MIN('Datos históricos de Credicorp ('!$D$12:$D$432) -> 45659 | H5: Max | J5: =MAX(BAP_Data_Raw[[#All],[Último]]) -> 402.27
D6: Fin | F6: =MAX('Datos históricos de Credicorp ('!$D$12:$D$432) -> 46269 | H6: Min | J6: =MIN(BAP_Data_Raw[[#All],[Último]]) -> 169.89
H7: Promedio | J7: =AVERAGE(BAP_Data_Raw[[#All],[Último]]) -> 276.71721
H8: Var Prom. (%) | J8: =AVERAGE(BAP_Data_Raw[% var.]) -> 0.0019433333
D12: Fecha | E12: Último | F12: Apertura | G12: Máximo | H12: Mínimo | I12: Vol. | J12: % var. | K12: Rango
D13: 46269 | E13: 382.53 | F13: 380.33 | G13: 385.26 | H13: 380.12 | I13: 149.37 | J13: -0.0043 | K13: ='Datos históricos de Credicorp ('!$F13-'Datos históricos de Credicorp ('!$G13 -> -4.93
D14: 46268 | E14: 384.19 | F14: 382.06 | G14: 386.2 | H14: 377.71 | I14: 215.16 | J14: 0.0122 | K14: ='Datos históricos de Credicorp ('!$F14-'Datos históricos de Credicorp ('!$G14 -> -4.14
D15: 46267 | E15: 379.56 | F15: 374.93 | G15: 383.8 | H15: 372.52 | I15: 278.6 | J15: 0.0189 | K15: ='Datos históricos de Credicorp ('!$F15-'Datos históricos de Credicorp ('!$G15 -> -8.87
D16: 46266 | E16: 372.52 | F16: 366.02 | G16: 374.36 | H16: 364.49 | I16: 293.93 | J16: 0.0168 | K16: ='Datos históricos de Credicorp ('!$F16-'Datos históricos de Credicorp ('!$G16 -> -8.34
D17: 46265 | E17: 366.38 | F17: 372.48 | G17: 373.47 | H17: 365.65 | I17: 389.09 | J17: -0.0055 | K17: ='Datos históricos de Credicorp ('!$F17-'Datos históricos de Credicorp ('!$G17 -> -0.99
D18: 46262 | E18: 368.4 | F18: 377.79 | G18: 377.79 | H18: 367.96 | I18: 554.8 | J18: -0.0129 | K18: ='Datos históricos de Credicorp ('!$F18-'Datos históricos de Credicorp ('!$G18 -> 0
D19: 46261 | E19: 373.2 | F19: 380.99 | G19: 383.01 | H19: 372.09 | I19: 310.58 | J19: -0.0244 | K19: ='Datos históricos de Credicorp ('!$F19-'Datos históricos de Credicorp ('!$G19 -> -2.02
D20: 46260 | E20: 382.55 | F20: 382.88 | G20: 385.97 | H20: 380.88 | I20: 240.57 | J20: -0.002 | K20: ='Datos históricos de Credicorp ('!$F20-'Datos históricos de Credicorp ('!$G20 -> -3.09
D21: 46259 | E21: 383.3 | F21: 381.54 | G21: 383.69 | H21: 375.21 | I21: 214.64 | J21: 0.0094 | K21: ='Datos históricos de Credicorp ('!$F21-'Datos históricos de Credicorp ('!$G21 -> -2.15
D22: 46258 | E22: 379.74 | F22: 379.09 | G22: 381.54 | H22: 375.18 | I22: 199.26 | J22: 0.002 | K22: ='Datos históricos de Credicorp ('!$F22-'Datos históricos de Credicorp ('!$G22 -> -2.45
D23: 46255 | E23: 378.97 | F23: 375.09 | G23: 379.83 | H23: 373.72 | I23: 192.83 | J23: 0.0237 | K23: ='Datos históricos de Credicorp ('!$F23-'Datos históricos de Credicorp ('!$G23 -> -4.74
D24: 46254 | E24: 370.21 | F24: 368.14 | G24: 377.91 | H24: 368.14 | I24: 298.47 | J24: 0.0033 | K24: ='Datos históricos de Credicorp ('!$F24-'Datos históricos de Credicorp ('!$G24 -> -9.77
... D73: 46183 | E73: 351.66 | F73: 346.84 | G73: 355.88 | H73: 343.41 | I73: 675.13 | J73: 0.0059 | K73: ='Datos históricos de Credicorp ('!$F73-'Datos históricos de Credicorp ('!$G73 -> -9.04
D74: 46182 | E74: 349.61 | F74: 341.7 | G74: 366.22 | H74: 339.09 | I74: 1.43M | J74: 0.0929 | K74: ='Datos históricos de Credicorp ('!$F74-'Datos históricos de Credicorp ('!$G74 -> -24.52
D75: 46181 | E75: 319.89 | F75: 317.99 | G75: 320.98 | H75: 299 | I75: 1.58M | J75: -0.0081 | K75: ='Datos históricos de Credicorp ('!$F75-'Datos históricos de Credicorp ('!$G75 -> -2.99
D76: 46178 | E76: 322.5 | F76: 322.37 | G76: 324.36 | H76: 310.75 | I76: 1.21M | J76: -0.0123 | K76: ='Datos históricos de Credicorp ('!$F76-'Datos históricos de Credicorp ('!$G76 -> -1.99
D77: 46177 | E77: 326.53 | F77: 330.5 | G77: 333.76 | H77: 325 | I77: 679.56 | J77: -0.0027 | K77: ='Datos históricos de Credicorp ('!$F77-'Datos históricos de Credicorp ('!$G77 -> -3.26
D78: 46176 | E78: 327.42 | F78: 339.58 | G78: 343.31 | H78: 327.42 | I78: 822.15 | J78: -0.048 | K78: ='Datos históricos de Credicorp ('!$F78-'Datos históricos de Credicorp ('!$G78 -> -3.73
D79: 46175 | E79: 343.93 | F79: 340.58 | G79: 344.88 | H79: 337.18 | I79: 256.36 | J79: 0.0099 | K79: ='Datos históricos de Credicorp ('!$F79-'Datos históricos de Credicorp ('!$G79 -> -4.3
D80: 46174 | E80: 340.56 | F80: 339.55 | G80: 343.8 | H80: 335.75 | I80: 307.63 | J80: -0.006 | K80: ='Datos históricos de Credicorp ('!$F80-'Datos históricos de Credicorp ('!$G80 -> -4.25
D81: 46171 | E81: 342.63 | F81: 340.79 | G81: 347.64 | H81: 337.67 | I81: 792.26 | J81: 0.0033 | K81: ='Datos históricos de Credicorp ('!$F81-'Datos históricos de Credicorp ('!$G81 -> -6.85
D82: 46170 | E82: 341.5 | F82: 345.77 | G82: 345.77 | H82: 336.82 | I82: 684.97 | J82: -0.0194 | K82: ='Datos históricos de Credicorp ('!$F82-'Datos históricos de Credicorp ('!$G82 -> 0
D83: 46169 | E83: 348.24 | F83: 351.24 | G83: 354.41 | H83: 343.08 | I83: 345.54 | J83: -0.01 | K83: ='Datos históricos de Credicorp ('!$F83-'Datos históricos de Credicorp ('!$G83 -> -3.17
D84: 46168 | E84: 351.75 | F84: 337.3 | G84: 353.61 | H84: 336.11 | I84: 309.55 | J84: 0.0522 | K84: ='Datos históricos de Credicorp ('!$F84-'Datos históricos de Credicorp ('!$G84 -> -16.31
D85: 46164 | E85: 334.3 | F85: 344.48 | G85: 350 | H85: 332.55 | I85: 454.92 | J85: -0.0282 | K85: ='Datos históricos de Credicorp ('!$F85-'Datos históricos de Credicorp ('!$G85 -> -5.52
D86: 46163 | E86: 344 | F86: 331.42 | G86: 345.77 | H86: 328.91 | I86: 531.81 | J86: 0.0322 | K86: ='Datos históricos de Credicorp ('!$F86-'Datos históricos de Credicorp ('!$G86 -> -14.35
D87: 46162 | E87: 333.27 | F87: 313.37 | G87: 335.55 | H87: 313.37 | I87: 668.89 | J87: 0.0554 | K87: ='Datos históricos de Credicorp ('!$F87-'Datos históricos de Credicorp ('!$G87 -> -22.18
D88: 46161 | E88: 315.79 | F88: 306.43 | G88: 316.57 | H88: 303.87 | I88: 648.77 | J88: 0.0393 | K88: ='Datos históricos de Credicorp ('!$F88-'Datos históricos de Credicorp ('!$G88 -> -10.14
... D110: 46129 | E110: 331.94 | F110: 341.22 | G110: 349.32 | H110: 328.42 | I110: 718.23 | J110: -0.0243 | K110: ='Datos históricos de Credicorp ('!$F110-'Datos históricos de Credicorp ('!$G110 -> -8.1
D111: 46128 | E111: 340.22 | F111: 318.12 | G111: 340.97 | H111: 316.05 | I111: 1.05M | J111: 0.075 | K111: ='Datos históricos de Credicorp ('!$F111-'Datos históricos de Credicorp ('!$G111 -> -22.85
D112: 46127 | E112: 316.49 | F112: 358.2 | G112: 358.2 | H112: 314.52 | I112: 1.33M | J112: -0.1149 | K112: ='Datos históricos de Credicorp ('!$F112-'Datos históricos de Credicorp ('!$G112 -> 0
D113: 46126 | E113: 357.59 | F113: 362.47 | G113: 362.47 | H113: 354.04 | I113: 347.19 | J113: -0.0104 | K113: ='Datos históricos de Credicorp ('!$F113-'Datos históricos de Credicorp ('!$G113 -> 0
D114: 46125 | E114: 361.34 | F114: 351.5 | G114: 365.46 | H114: 347.38 | I114: 644.39 | J114: 0.0341 | K114: ='Datos históricos de Credicorp ('!$F114-'Datos históricos de Credicorp ('!$G114 -> -13.96
...
